Workbook

Sheet TUDB
A1: TU DARE Angler Science DB
A2: Database | B2: Dev: DBParsing_241015_v01.xlsm
A3: Download | B3: 45580 | D3: UTC Correction
A4: Observations | B4: 2320 | D4: -6
A5: Year Load | B5: 2024 | AL5: =COUNTIF(TU_DB[None (Disturbance)],1) -> 1295
BO6: reset col references to HUC12 sheet
A7: Database | B7: ObsNo | C7: Observation Date/Time-UTC | D7: Observation Date/Time-Local | E7: Observation Date-Local | F7: Year | G7: Month No. | H7: ObserverID | I7: Monitoring Site | J7: Longitude | K7: Latitude | L7: Zonal | M7: Photo No. | N7: Photo Flag | O7: Public | P7: 5n1 Flag | Q7: ALK Bin (ppm) | R7: HRD Bin (ppm) | S7: NO2 Bin (5n1) (ppm) | T7: NO3 Bin (5n1) (ppm) | U7: pH Bin | V7: Phos Flag | W7: Orthophosphate (ppb) | X7: Water Temp Flag | Y7: Water Temperature (oF) | Z7: 2n1 Flag | AA7: NO2 Bin (2n1) (ppm) | AB7: NO3 Bin (2n1) (ppm) | AC7: Source | AD7: Disturbances | AE7: Fish Barrier | AF7: Bank Erosion | AG7: Trash | AH7: Pipe/Drain Outflow | AI7: Livestock in Water | AJ7: Algal Bloom | AK7: Fish Kill | AL7: None (Disturbance) | AM7: Dis: Not Reported | AN7: Water Level | AO7: Water Level Flag | AP7: Clarity | AQ7: Clarity Flag | AR7: Weather | AS7: Regional Rainfall | AT7: Local Thunderstorm | AU7: Snowmelt | AV7: None (Weather) | AW7: Not Reported (Weather) | AX7: Observation Comments | AY7: Obs Com Flag | AZ7: Bank Erosion4 | BA7: Trash5 | BB7: Pipe Drain6 | BC7: Livestock in Water2 | BD7: Algal Bloom3 | BE7: Fish Kill4 | BF7: None7 | BG7: Dis: Not Reported8 | BH7: All Streams | BI7: Primary Stream | BJ7: Trout Stream Flag | BK7: Brook Trout Stream Flag | BL7: Plotting Zone | BM7: TU Chapter Area | BN7: Observer Chapter Affiliation | BO7: HUC12 Code | BP7: HUC12 Name | BQ7: HUC10 Name | BR7: Column1
A8: Dev: DBParsing_231030_v01.xlsm | B8: x31pFiQ1h6Ck2GeazKZQ | C8: 45587.677 | D8: 45587.427 | E8: 45587 | F8: 2024 | G8: 10 | H8: 3ewh0JhsqndewkOhEmNvJ9cb0n83 | I8: Rush River @ 570th Ave | J8: -92.142296 | K8: 44.790396 | M8: 2024-10-22 11:14:10.552952.jpg-0 | N8: 1 | P8: 1 | Q8: 180 | R8: 180 | U8: 7 | V8: 1 | W8: 100 | X8: 1 | Y8: 50 | Z8: 1 | AA8: 0 | AB8: 2 | AC8: River/Stream | AD8: None | AE8: 0 | AF8: 0 | AG8: 0 | AH8: 0 | AI8: 0 | AJ8: 0 | AK8: 0 | AL8: 1 | AM8: 0 | AN8: Baseflow | AO8: 1 | AP8: Clear | AQ8: 1 | AR8: None | AS8: 0 | AT8: 0 | AU8: 0 | AV8: 0 | AW8: 0 | AX8: sample location moved to 200ft below Co Rd P bridge. better cell phone coverage. much easier access to water | AY8: 1 | AZ8: Absent | BA8: Absent | BB8: Absent | BC8: Absent | BD8: Absent | BE8: Absent | BF8: Absent | BG8: Present | BH8: Recorded | BJ8: 1 | BK8: 1 | BL8: 1 | BM8: Kiap-TU-Wish | BN8: Kiap-TU-Wish | BO8: 070500051003 | BP8: Cady Creek | BQ8: 0705000510
A9: Dev: DBParsing_231030_v01.xlsm | B9: WjE9qCLHdWkQVBbZYn1m | C9: 45580.679 | D9: 45580.429 | E9: 45580 | F9: 2024 | G9: 10 | H9: 7a7IFD1YT3aDXB8CbnSJjn1oLRC2 | I9: Isabelle Creek @ County Rd. EE | J9: -92.442941 | K9: 44.621467 | N9: 0 | P9: 1 | Q9: 0 | R9: 30 | U9: 7 | V9: 1 | W9: 0 | X9: 1 | Y9: 42 | Z9: 1 | AA9: 0 | AB9: 0 | AC9: River/Stream | AD9: None | AE9: 0 | AF9: 0 | AG9: 0 | AH9: 0 | AI9: 0 | AJ9: 0 | AK9: 0 | AL9: 1 | AM9: 0 | AN9: Baseflow | AO9: 1 | AP9: Clear | AQ9: 1 | AR9: None | AS9: 0 | AT9: 0 | AU9: 0 | AV9: 0 | AW9: 0 | AY9: 0 | AZ9: Absent | BA9: Absent | BB9: Absent | BC9: Absent | BD9: Absent | BE9: Absent | BF9: Absent | BG9: Present | BH9: Recorded | BJ9: 1 | BM9: Kiap-TU-Wish | BN9: Unknown | BO9: 070400010701 | BP9: Isabelle Creek | BQ9: 0704000107
A10: Dev: DBParsing_231030_v01.xlsm | B10: vSO8Z1gbM7hfp3OtebbB | C10: 45576.703 | D10: 45576.453 | E10: 45576 | F10: 2024 | G10: 10 | H10: VCf2q8JFBSOaJbmxiMqirI5xKFn2 | I10: Plum Creek @ Plum City Park | J10: -92.189548 | K10: 44.632814 | N10: 0 | P10: 1 | Q10: 120 | R10: 180 | U10: 7 | V10: 1 | W10: 0 | X10: 1 | Y10: 59 | Z10: 0 | AA10: 0 | AB10: 2 | AC10: River/Stream | AE10: -1 | AF10: -1 | AG10: -1 | AH10: -1 | AI10: -1 | AJ10: -1 | AK10: -1 | AL10: -1 | AM10: 1 | AN10: Mid-stage | AO10: 1 | AP10: Clear | AQ10: 1 | AR10: None | AS10: 0 | AT10: 0 | AU10: 0 | AV10: 0 | AW10: 0 | AY10: 0 | AZ10: No Data | BA10: No Data | BB10: No Data | BC10: No Data | BD10: No Data | BE10: No Data | BF10: No Data | BG10: No Data | BH10: No Data | BI10: Plum Creek | BJ10: 1 | BK10: 1 | BL10: 1 | BM10: Kiap-TU-Wish | BN10: Kiap-TU-Wish | BO10: 070500051101 | BP10: Nugget Lake-Plum Creek | BQ10: 0705000511
A11: Dev: DBParsing_231030_v01.xlsm | B11: ef3rXz53Wbd4V4SY7bHX | C11: 45576.678 | D11: 45576.428 | E11: 45576 | F11: 2024 | G11: 10 | H11: VCf2q8JFBSOaJbmxiMqirI5xKFn2 | I11: Pine Creek @ County Rd. AA | J11: -92.283925 | K11: 44.542201 | N11: 0 | P11: 1 | Q11: 180 | R11: 180 | U11: 7.5 | V11: 1 | W11: 0 | X11: 1 | Y11: 52 | Z11: 1 | AA11: 0 | AB11: 5 | AC11: River/Stream | AE11: -1 | AF11: -1 | AG11: -1 | AH11: -1 | AI11: -1 | AJ11: -1 | AK11: -1 | AL11: -1 | AM11: 1 | AN11: Baseflow | AO11: 1 | AP11: Clear | AQ11: 1 | AR11: None | AS11: 0 | AT11: 0 | AU11: 0 | AV11: 0 | AW11: 0 | AY11: 0 | AZ11: No Data | BA11: No Data | BB11: No Data | BC11: No Data | BD11: No Data | BE11: No Data | BF11: No Data | BG11: No Data | BH11: No Data | BI11: Pine Creek | BJ11: 1 | BK11: 1 | BL11: 1 | BM11: Wisconsin Clear Water | BN11: Kiap-TU-Wish | BO11: 070400010702 | BP11: Pine Creek | BQ11: 0704000107
A12: Dev: DBParsing_231030_v01.xlsm | B12: UC3FLgahXBrYRatX6I9T | C12: 45575.627 | D12: 45575.377 | E12: 45575 | F12: 2024 | G12: 10 | H12: VQ9bNtzttGcXOEuaXrEAEYLfT103 | J12: -92.614863 | K12: 44.454619 | N12: 0 | P12: 1 | Q12: 120 | R12: 180 | U12: 7.5 | V12: 1 | W12: 0 | X12: 1 | Y12: 50 | Z12: 1 | AA12: 0 | AB12: 10 | AC12: Springs | AD12: None | AE12: 0 | AF12: 0 | AG12: 0 | AH12: 0 | AI12: 0 | AJ12: 0 | AK12: 0 | AL12: 1 | AM12: 0 | AN12: Baseflow | AO12: 1 | AP12: Clear | AQ12: 1 | AR12: None | AS12: 0 | AT12: 0 | AU12: 0 | AV12: 0 | AW12: 0 | AY12: 0 | AZ12: Absent | BA12: Absent | BB12: Absent | BC12: Absent | BD12: Absent | BE12: Absent | BF12: Absent | BG12: Present | BH12: Recorded | BI12: Hay Creek | BJ12: 1 | BM12: Twin Cities (TCTU) | BN12: Hiawatha | BO12: 070400010401 | BP12: Hay Creek | BQ12: 0704000104
A13: Dev: DBParsing_231030_v01.xlsm | B13: RlfkVu0i6kHSPOkP0fg4 | C13: 45569.626 | D13: 45569.376 | E13: 45569 | F13: 2024 | G13: 10 | H13: 80reiKTTqGYqqpgYAhPwqypFwak1 | J13: -92.195375 | K13: 43.811325 | M13: 2024-10-04 10:02:08.954120.jpg-0 | N13: 1 | P13: 0 | V13: 1 | W13: 0 | X13: 1 | Y13: 48 | Z13: 1 | AA13: 0 | AB13: 5 | AC13: River/Stream | AD13: None | AE13: 0 | AF13: 0 | AG13: 0 | AH13: 0 | AI13: 0 | AJ13: 0 | AK13: 0 | AL13: 1 | AM13: 0 | AN13: Mid-stage | AO13: 1 | AP13: Murky | AQ13: 1 | AR13: None | AS13: 0 | AT13: 0 | AU13: 0 | AV13: 0 | AW13: 0 | AX13: Lost Creek is up a bit but no rain of late. looks murky. not sure why. | AY13: 1 | AZ13: Absent | BA13: Absent | BB13: Absent | BC13: Absent | BD13: Absent | BE13: Absent | BF13: Absent | BG13: Present | BH13: Recorded | BI13: Bear Creek | BJ13: 1 | BM13: Hiawatha | BN13: Hiawatha | BO13: 070400080207 | BP13: Bear Creek | BQ13: 0704000802
A14: Dev: DBParsing_231030_v01.xlsm | B14: 1dLTqjMBsqW0BBhzAec8 | C14: 45569.616 | D14: 45569.366 | E14: 45569 | F14: 2024 | G14: 10 | H14: 80reiKTTqGYqqpgYAhPwqypFwak1 | I14: Other Locations | J14: -92.173817 | K14: 43.822348 | M14: 2024-10-04 09:47:26.558896.jpg-0 | N14: 1 | P14: 0 | V14: 1 | W14: 0 | X14: 1 | Y14: 53 | Z14: 1 | AA14: 0 | AB14: 2 | AC14: River/Stream | AD14: None | AE14: 0 | AF14: 0 | AG14: 0 | AH14: 0 | AI14: 0 | AJ14: 0 | AK14: 0 | AL14: 1 | AM14: 0 | AN14: Mid-stage | AO14: 1 | AP14: Murky | AQ14: 1 | AR14: None | AS14: 0 | AT14: 0 | AU14: 0 | AV14: 0 | AW14: 0 | AY14: 0 | AZ14: Absent | BA14: Absent | BB14: Absent | BC14: Absent | BD14: Absent | BE14: Absent | BF14: Absent | BG14: Present | BH14: Recorded | BI14: North Branch Root River | BM14: Hiawatha | BN14: Hiawatha | BO14: 070400080108 | BP14: North Branch Root River | BQ14: 0704000801
A15: Dev: DBParsing_231030_v01.xlsm | B15: EFF0ZxM4If7mM5H7JoRZ | C15: 45568.724 | D15: 45568.474 | E15: 45568 | F15: 2024 | G15: 10 | H15: VQ9bNtzttGcXOEuaXrEAEYLfT103 | J15: -92.689313 | K15: 43.824756 | N15: 0 | P15: 1 | Q15: 0 | R15: 60 | U15: 7.5 | V15: 1 | W15: 0 | X15: 1 | Y15: 56 | Z15: 1 | AA15: 0 | AB15: 0 | AC15: River/Stream | AD15: None | AE15: 0 | AF15: 0 | AG15: 0 | AH15: 0 | AI15: 0 | AJ15: 0 | AK15: 0 | AL15: 1 | AM15: 0 | AN15: Baseflow | AO15: 1 | AP15: Clear | AQ15: 1 | AR15: None | AS15: 0 | AT15: 0 | AU15: 0 | AV15: 0 | AW15: 0 | AY15: 0 | AZ15: Absent | BA15: Absent | BB15: Absent | BC15: Absent | BD15: Absent | BE15: Absent | BF15: Absent | BG15: Present | BH15: Recorded | BI15: North Branch Root River | BM15: Hiawatha | BN15: Hiawatha | BO15: 070400080101 | BP15: Headwaters North Branch Root River | BQ15: 0704000801
A16: Dev: DBParsing_231030_v01.xlsm | B16: oGdLeYPS4ZcTpXtXYKNB | C16: 45568.689 | D16: 45568.439 | E16: 45568 | F16: 2024 | G16: 10 | H16: VQ9bNtzttGcXOEuaXrEAEYLfT103 | J16: -92.488043 | K16: 43.645086 | N16: 0 | P16: 1 | Q16: 0 | R16: 0 | U16: 7.5 | V16: 1 | W16: 0 | X16: 1 | Y16: 56 | Z16: 1 | AA16: 0 | AB16: 0 | AC16: River/Stream | AD16: None | AE16: 0 | AF16: 0 | AG16: 0 | AH16: 0 | AI16: 0 | AJ16: 0 | AK16: 0 | AL16: 1 | AM16: 0 | AN16: Baseflow | AO16: 1 | AP16: Clear | AQ16: 1 | AR16: None | AS16: 0 | AT16: 0 | AU16: 0 | AV16: 0 | AW16: 0 | AY16: 0 | AZ16: Absent | BA16: Absent | BB16: Absent | BC16: Absent | BD16: Absent | BE16: Absent | BF16: Absent | BG16: Present | BH16: Recorded | BI16: South Branch Root River | BM16: Hiawatha | BN16: Hiawatha | BO16: 070400080401 | BP16: Headwaters South Branch Root River | BQ16: 0704000804
A17: Dev: DBParsing_231030_v01.xlsm | B17: TN2fl39g5bG9uMUc1jQt | C17: 45567.959 | D17: 45567.709 | E17: 45567 | F17: 2024 | G17: 10 | H17: H4dZvxTdViejefqREn5k066JVZG3 | J17: -92.23632 | K17: 44.230641 | M17: 2024-10-02 18:01:05.677657.jpg-0 | N17: 1 | P17: 1 | Q17: 40 | R17: 180 | U17: 7 | V17: 1 | W17: 100 | X17: 1 | Y17: 64 | Z17: 1 | AA17: 0 | AB17: 5 | AC17: River/Stream | AD17: None | AE17: 0 | AF17: 0 | AG17: 0 | AH17: 0 | AI17: 0 | AJ17: 0 | AK17: 0 | AL17: 1 | AM17: 0 | AN17: Baseflow | AO17: 1 | AP17: Clear | AQ17: 1 | AR17: None | AS17: 0 | AT17: 0 | AU17: 0 | AV17: 0 | AW17: 0 | AX17: long creek downstream from Cnty 8 bridge | AY17: 1 | AZ17: Absent | BA17: Absent | BB17: Absent | BC17: Absent | BD17: Absent | BE17: Absent | BF17: Absent | BG17: Present | BH17: Recorded | BI17: Long Creek | BJ17: 1 | BK17: 1 | BL17: 1 | BM17: Hiawatha | BN17: Hiawatha | BO17: 070400040505 | BP17: Long Creek | BQ17: 0704000405
A18: Dev: DBParsing_231030_v01.xlsm | B18: y0n1PBzO2OEMuMKcHxhn | C18: 45567.94 | D18: 45567.69 | E18: 45567 | F18: 2024 | G18: 10 | H18: H4dZvxTdViejefqREn5k066JVZG3 | J18: -92.149234 | K18: 44.248828 | M18: 2024-10-02 17:33:23.653241.jpg-0 | N18: 1 | P18: 1 | Q18: 80 | R18: 0 | U18: 7 | V18: 1 | W18: 100 | X18: 1 | Y18: 63 | Z18: 1 | AA18: 0 | AB18: 5 | AC18: River/Stream | AD18: None | AE18: 0 | AF18: 0 | AG18: 0 | AH18: 0 | AI18: 0 | AJ18: 0 | AK18: 0 | AL18: 1 | AM18: 0 | AN18: Baseflow | AO18: 1 | AP18: Clear | AQ18: 1 | AR18: None | AS18: 0 | AT18: 0 | AU18: 0 | AV18: 0 | AW18: 0 | AX18: West Indian by parking lot | AY18: 1 | AZ18: Absent | BA18: Absent | BB18: Absent | BC18: Absent | BD18: Absent | BE18: Absent | BF18: Absent | BG18: Present | BH18: Recorded | BJ18: 1 | BK18: 1 | BL18: 1 | BM18: Hiawatha | BN18: Hiawatha | BO18: 070400040510 | BP18: West Indian Creek | BQ18: 0704000405
A19: Dev: DBParsing_231030_v01.xlsm | B19: rGj17OQRpq7y2LYBvGJg | C19: 45567.787 | D19: 45567.537 | E19: 45567 | F19: 2024 | G19: 10 | H19: GFBS1bSIACUVgSmsBlw0BYkB9i72 | J19: -90.887301 | K19: 43.733607 | M19: 2024-10-02 13:52:50.878327.jpg-0 | N19: 1 | P19: 1 | Q19: 180 | R19: 120 | U19: 7.5 | V19: 1 | W19: 0 | X19: 1 | Y19: 55 | Z19: 1 | AA19: 0 | AB19: 2 | AC19: River/Stream | AD19: None | AE19: 0 | AF19: 0 | AG19: 0 | AH19: 0 | AI19: 0 | AJ19: 0 | AK19: 0 | AL19: 1 | AM19: 0 | AN19: Baseflow | AO19: 1 | AP19: Clear | AQ19: 1 | AR19: None | AS19: 0 | AT19: 0 | AU19: 0 | AV19: 0 | AW19: 0 | AY19: 0 | AZ19: Absent | BA19: Absent | BB19: Absent | BC19: Absent | BD19: Absent | BE19: Absent | BF19: Absent | BG19: Present | BH19: Recorded | BI19: Rullands Coulee Creek | BJ19: 1 | BM19: Coulee Region | BN19: TU Staff | BO19: 070600010101 | BP19: Timber Coulee Creek | BQ19: 0706000101
A20: Dev: DBParsing_231030_v01.xlsm | B20: WXfDFWuy6t485zEe9Y3m | C20: 45565.689 | D20: 45565.439 | E20: 45565 | F20: 2024 | G20: 9 | H20: 80reiKTTqGYqqpgYAhPwqypFwak1 | J20: -92.649573 | K20: 44.075224 | N20: 0 | P20: 0 | V20: 0 | X20: 1 | Y20: 56 | Z20: 1 | AA20: 0 | AB20: 5 | AC20: River/Stream | AD20: None | AE20: 0 | AF20: 0 | AG20: 0 | AH20: 0 | AI20: 0 | AJ20: 0 | AK20: 0 | AL20: 1 | AM20: 0 | AN20: Baseflow | AO20: 1 | AP20: Murky | AQ20: 1 | AR20: None | AS20: 0 | AT20: 0 | AU20: 0 | AV20: 0 | AW20: 0 | AY20: 0 | AZ20: Absent | BA20: Absent | BB20: Absent | BC20: Absent | BD20: Absent | BE20: Absent | BF20: Absent | BG20: Present | BH20: Recorded | BM20: Hiawatha | BN20: Hiawatha | BO20: 070400040205 | BP20: South Branch Middle Fork Zumbro River | BQ20: 0704000402
A21: Dev: DBParsing_231030_v01.xlsm | B21: LXb54yJfypIJj3msK3G0 | C21: 45565.631 | D21: 45565.381 | E21: 45565 | F21: 2024 | G21: 9 | H21: VQ9bNtzttGcXOEuaXrEAEYLfT103 | J21: -91.970468 | K21: 44.005512 | N21: 0 | P21: 1 | Q21: 80 | R21: 180 | U21: 7 | V21: 1 | W21: 100 | X21: 1 | Y21: 56 | Z21: 1 | AA21: 0 | AB21: 2 | AC21: Springs | AD21: None | AE21: 0 | AF21: 0 | AG21: 0 | AH21: 0 | AI21: 0 | AJ21: 0 | AK21: 0 | AL21: 1 | AM21: 0 | AN21: Baseflow | AO21: 1 | AP21: Clear | AQ21: 1 | AR21: None | AS21: 0 | AT21: 0 | AU21: 0 | AV21: 0 | AW21: 0 | AY21: 0 | AZ21: Absent | BA21: Absent | BB21: Absent | BC21: Absent | BD21: Absent | BE21: Absent | BF21: Absent | BG21: Present | BH21: Recorded | BI21: South Fork Whitewater River | BJ21: 1 | BM21: Win Cres | BN21: Hiawatha | BO21: 070400030307 | BP21: Lower South Fork Whitewater River | BQ21: 0704000303
A22: Dev: DBParsing_231030_v01.xlsm | B22: k2tw9pMkejSiuCOoGngm | C22: 45562.69 | D22: 45562.44 | E22: 45562 | F22: 2024 | G22: 9 | H22: VCf2q8JFBSOaJbmxiMqirI5xKFn2 | I22: Plum Creek @ Plum City Park | J22: -92.189503 | K22: 44.632802 | N22: 0 | P22: 1 | Q22: 120 | R22: 180 | U22: 7 | V22: 1 | W22: 0 | X22: 1 | Y22: 60 | Z22: 1 | AA22: 0 | AB22: 2 | AC22: River/Stream | AE22: -1 | AF22: -1 | AG22: -1 | AH22: -1 | AI22: -1 | AJ22: -1 | AK22: -1 | AL22: -1 | AM22: 1 | AN22: Mid-stage | AO22: 1 | AP22: Clear | AQ22: 1 | AR22: None | AS22: 0 | AT22: 0 | AU22: 0 | AV22: 0 | AW22: 0 | AY22: 0 | AZ22: No Data | BA22: No Data | BB22: No Data | BC22: No Data | BD22: No Data | BE22: No Data | BF22: No Data | BG22: No Data | BH22: No Data | BI22: Plum Creek | BJ22: 1 | BK22: 1 | BL22: 1 | BM22: Kiap-TU-Wish | BN22: Kiap-TU-Wish | BO22: 070500051101 | BP22: Nugget Lake-Plum Creek | BQ22: 0705000511
A23: Dev: DBParsing_231030_v01.xlsm | B23: ATecdl8SnqOXVtJPZ01R | C23: 45562.675 | D23: 45562.425 | E23: 45562 | F23: 2024 | G23: 9 | H23: VQ9bNtzttGcXOEuaXrEAEYLfT103 | J23: -91.878951 | K23: 43.878991 | N23: 0 | P23: 1 | Q23: 80 | R23: 120 | U23: 7.5 | V23: 1 | W23: 100 | X23: 1 | Y23: 56 | Z23: 1 | AA23: 0 | AB23: 5 | AC23: Springs | AD23: None | AE23: 0 | AF23: 0 | AG23: 0 | AH23: 0 | AI23: 0 | AJ23: 0 | AK23: 0 | AL23: 1 | AM23: 0 | AN23: Baseflow | AO23: 1 | AP23: Clear | AQ23: 1 | AR23: None | AS23: 0 | AT23: 0 | AU23: 0 | AV23: 0 | AW23: 0 | AY23: 0 | AZ23: Absent | BA23: Absent | BB23: Absent | BC23: Absent | BD23: Absent | BE23: Absent | BF23: Absent | BG23: Present | BH23: Recorded | BI23: 0 | BJ23: 1 | BK23: 1 | BL23: 1 | BM23: Win Cres | BN23: Hiawatha | BO23: 070400080503 | BP23: Pine Creek | BQ23: 0704000805
A24: Dev: DBParsing_231030_v01.xlsm | B24: 315eGmQ1kn6o4MrrroBq | C24: 45561.698 | D24: 45561.448 | E24: 45561 | F24: 2024 | G24: 9 | H24: VCf2q8JFBSOaJbmxiMqirI5xKFn2 | I24: Pine Creek @ County Rd. AA | J24: -92.284235 | K24: 44.542189 | N24: 0 | P24: 1 | Q24: 180 | R24: 180 | U24: 7.5 | V24: 1 | W24: 0 | X24: 1 | Y24: 56 | Z24: 1 | AA24: 0 | AB24: 5 | AC24: River/Stream | AE24: -1 | AF24: -1 | AG24: -1 | AH24: -1 | AI24: -1 | AJ24: -1 | AK24: -1 | AL24: -1 | AM24: 1 | AN24: Baseflow | AO24: 1 | AP24: Clear | AQ24: 1 | AR24: None | AS24: 0 | AT24: 0 | AU24: 0 | AV24: 0 | AW24: 0 | AY24: 0 | AZ24: No Data | BA24: No Data | BB24: No Data | BC24: No Data | BD24: No Data | BE24: No Data | BF24: No Data | BG24: No Data | BH24: No Data | BI24: Pine Creek | BJ24: 1 | BK24: 1 | BL24: 1 | BM24: Wisconsin Clear Water | BN24: Kiap-TU-Wish | BO24: 070400010702 | BP24: Pine Creek | BQ24: 0704000107
A25: Dev: DBParsing_231030_v01.xlsm | B25: x6kNUFvkPJdmwD2Cmhr6 | C25: 45560.782 | D25: 45560.532 | E25: 45560 | F25: 2024 | G25: 9 | H25: VQ9bNtzttGcXOEuaXrEAEYLfT103 | J25: -91.580957 | K25: 43.641461 | N25: 0 | P25: 1 | Q25: 0 | R25: 60 | U25: 7 | V25: 1 | W25: 0 | X25: 1 | Y25: 52 | Z25: 1 | AA25: 0 | AB25: 5 | AC25: River/Stream | AD25: None | AE25: 0 | AF25: 0 | AG25: 0 | AH25: 0 | AI25: 0 | AJ25: 0 | AK25: 0 | AL25: 1 | AM25: 0 | AN25: Baseflow | AO25: 1 | AP25: Clear | AQ25: 1 | AR25: None | AS25: 0 | AT25: 0 | AU25: 0 | AV25: 0 | AW25: 0 | AY25: 0 | AZ25: Absent | BA25: Absent | BB25: Absent | BC25: Absent | BD25: Absent | BE25: Absent | BF25: Absent | BG25: Present | BH25: Recorded | BJ25: 1 | BM25: Win Cres | BN25: Hiawatha | BO25: 070400080805 | BP25: Beaver Creek | BQ25: 0704000808
A26: Dev: DBParsing_231030_v01.xlsm | B26: MPpX1Gv13cIjfEk9vvIF | C26: 45560.76 | D26: 45560.51 | E26: 45560 | F26: 2024 | G26: 9 | H26: VQ9bNtzttGcXOEuaXrEAEYLfT103 | J26: -91.373367 | K26: 43.603532 | N26: 0 | P26: 1 | Q26: 80 | R26: 180 | U26: 8 | V26: 1 | W26: 0 | X26: 1 | Y26: 60 | Z26: 1 | AA26: 0 | AB26: 2 | AC26: River/Stream | AD26: None | AE26: 0 | AF26: 0 | AG26: 0 | AH26: 0 | AI26: 0 | AJ26: 0 | AK26: 0 | AL26: 1 | AM26: 0 | AN26: Baseflow | AO26: 1 | AP26: Murky | AQ26: 1 | AR26: None | AS26: 0 | AT26: 0 | AU26: 0 | AV26: 0 | AW26: 0 | AY26: 0 | AZ26: Absent | BA26: Absent | BB26: Absent | BC26: Absent | BD26: Absent | BE26: Absent | BF26: Absent | BG26: Present | BH26: Recorded | BI26: Crooked Creek | BJ26: 1 | BM26: Win Cres | BN26: Hiawatha | BO26: 070600010203 | BP26: Clear Creek-Crooked Creek | BQ26: 0706000102
A27: Dev: DBParsing_231030_v01.xlsm | B27: F7QLJSHtMpAbgyE7oAgZ | C27: 45560.742 | D27: 45560.492 | E27: 45560 | F27: 2024 | G27: 9 | H27: VQ9bNtzttGcXOEuaXrEAEYLfT103 | J27: -91.413098 | K27: 43.54054 | N27: 0 | P27: 1 | Q27: 80 | R27: 120 | U27: 7.5 | V27: 1 | W27: 0 | X27: 0 | Z27: 1 | AA27: 0 | AB27: 5 | AC27: River/Stream | AD27: None | AE27: 0 | AF27: 0 | AG27: 0 | AH27: 0 | AI27: 0 | AJ27: 0 | AK27: 0 | AL27: 1 | AM27: 0 | AN27: Baseflow | AO27: 1 | AP27: Murky | AQ27: 1 | AR27: None | AS27: 0 | AT27: 0 | AU27: 0 | AV27: 0 | AW27: 0 | AY27: 0 | AZ27: Absent | BA27: Absent | BB27: Absent | BC27: Absent | BD27: Absent | BE27: Absent | BF27: Absent | BG27: Present | BH27: Recorded | BI27: Winnebago Creek | BJ27: 1 | BK27: 1 | BL27: 1 | BM27: Win Cres | BN27: Hiawatha | BO27: 070600010401 | BP27: Upper Winnebago Creek | BQ27: 0706000104
A28: Dev: DBParsing_231030_v01.xlsm | B28: K35jlV9fHdkoplQIGzc1 | C28: 45560.703 | D28: 45560.453 | E28: 45560 | F28: 2024 | G28: 9 | H28: VQ9bNtzttGcXOEuaXrEAEYLfT103 | J28: -91.569788 | K28: 43.502341 | N28: 0 | P28: 1 | Q28: 120 | R28: 180 | U28: 7.5 | V28: 1 | W28: 0 | X28: 1 | Y28: 52 | Z28: 1 | AA28: 0 | AB28: 0 | AC28: River/Stream | AD28: None | AE28: 0 | AF28: 0 | AG28: 0 | AH28: 0 | AI28: 0 | AJ28: 0 | AK28: 0 | AL28: 1 | AM28: 0 | AN28: Baseflow | AO28: 1 | AP28: Clear | AQ28: 1 | AR28: None | AS28: 0 | AT28: 0 | AU28: 0 | AV28: 0 | AW28: 0 | AY28: 0 | AZ28: Absent | BA28: Absent | BB28: Absent | BC28: Absent | BD28: Absent | BE28: Absent | BF28: Absent | BG28: Present | BH28: Recorded | BI28: Bee Creek | BJ28: 1 | BK28: 1 | BL28: 1 | BM28: Win Cres | BN28: Hiawatha | BO28: 070600020502 | BP28: Waterloo Creek | BQ28: 0706000205
A29: Dev: DBParsing_231030_v01.xlsm | B29: 5Br5G43UJ3veHyyBKWIO | C29: 45560.681 | D29: 45560.431 | E29: 45560 | F29: 2024 | G29: 9 | H29: wOnBJTAV2CZK06CRnr5oUK45EDv1 | J29: -90.471891 | K29: 43.047571 | M29: 2024-09-25 11:20:13.472036.jpg-0 | N29: 1 | P29: 1 | Q29: 180 | R29: 120 | U29: 7.5 | V29: 1 | W29: 0 | X29: 1 | Y29: 57 | Z29: 1 | AA29: 0 | AB29: 5 | AC29: River/Stream | AD29: Bank Erosion,Livestock in Water | AE29: 0 | AF29: 1 | AG29: 0 | AH29: 0 | AI29: 1 | AJ29: 0 | AK29: 0 | AL29: 0 | AM29: 0 | AN29: Mid-stage | AO29: 1 | AP29: Murky | AQ29: 1 | AR29: None | AS29: 0 | AT29: 0 | AU29: 0 | AV29: 0 | AW29: 0 | AX29: recent rain up to 4 inches depending on where. water was 3 feet higher recently | AY29: 1 | AZ29: Absent | BA29: Present | BB29: Absent | BC29: Absent | BD29: Present | BE29: Absent | BF29: Absent | BG29: Absent | BH29: Recorded | BI29: Blue River | BJ29: 1 | BM29: Harry & Laura Nohr | BN29: US FWS | BO29: 070700051406 | BP29: Big Rock Branch-Blue River | BQ29: 0707000514
A30: Dev: DBParsing_231030_v01.xlsm | B30: GMwLSDlBA4LtNP55jHS0 | C30: 45560.674 | D30: 45560.424 | E30: 45560 | F30: 2024 | G30: 9 | H30: VQ9bNtzttGcXOEuaXrEAEYLfT103 | J30: -91.814811 | K30: 43.597239 | N30: 0 | P30: 1 | Q30: 80 | R30: 180 | U30: 7.5 | V30: 1 | W30: 0 | X30: 1 | Y30: 54 | Z30: 1 | AA30: 0 | AB30: 5 | AC30: River/Stream | AD30: None | AE30: 0 | AF30: 0 | AG30: 0 | AH30: 0 | AI30: 0 | AJ30: 0 | AK30: 0 | AL30: 1 | AM30: 0 | AN30: Baseflow | AO30: 1 | AP30: Clear | AQ30: 1 | AR30: None | AS30: 0 | AT30: 0 | AU30: 0 | AV30: 0 | AW30: 0 | AY30: 0 | AZ30: Absent | BA30: Absent | BB30: Absent | BC30: Absent | BD30: Absent | BE30: Absent | BF30: Absent | BG30: Present | BH30: Recorded | BI30: Wisel Creek | BJ30: 1 | BK30: 1 | BL30: 1 | BM30: Win Cres | BN30: Hiawatha | BO30: 070400080802 | BP30: Wisel Creek | BQ30: 0704000808
A31: Dev: DBParsing_231030_v01.xlsm | B31: h3OyYyOOmRe7elBpNakO | C31: 45560.644 | D31: 45560.394 | E31: 45560 | F31: 2024 | G31: 9 | H31: VQ9bNtzttGcXOEuaXrEAEYLfT103 | J31: -91.79196 | K31: 43.67377 | N31: 0 | P31: 1 | Q31: 120 | R31: 180 | U31: 8 | V31: 1 | W31: 0 | X31: 1 | Y31: 54 | Z31: 1 | AA31: 0 | AB31: 5 | AC31: River/Stream | AD31: None | AE31: 0 | AF31: 0 | AG31: 0 | AH31: 0 | AI31: 0 | AJ31: 0 | AK31: 0 | AL31: 1 | AM31: 0 | AN31: Baseflow | AO31: 1 | AP31: Clear | AQ31: 1 | AR31: None | AS31: 0 | AT31: 0 | AU31: 0 | AV31: 0 | AW31: 0 | AY31: 0 | AZ31: Absent | BA31: Absent | BB31: Absent | BC31: Absent | BD31: Absent | BE31: Absent | BF31: Absent | BG31: Present | BH31: Recorded | BI31: 0 | BJ31: 1 | BK31: 1 | BL31: 1 | BM31: Win Cres | BN31: Hiawatha | BO31: 070400080803 | BP31: Middle South Fork Root River | BQ31: 0704000808
A32: Dev: DBParsing_231030_v01.xlsm | B32: fDbzZMAsLMrO5uJSuHyt | C32: 45559.709 | D32: 45559.459 | E32: 45559 | F32: 2024 | G32: 9 | H32: VQ9bNtzttGcXOEuaXrEAEYLfT103 | J32: -92.293851 | K32: 43.727874 | N32: 0 | P32: 1 | Q32: 80 | R32: 180 | U32: 7.5 | V32: 1 | W32: 0 | X32: 1 | Y32: 57 | Z32: 1 | AA32: 0 | AB32: 5 | AC32: River/Stream | AD32: None | AE32: 0 | AF32: 0 | AG32: 0 | AH32: 0 | AI32: 0 | AJ32: 0 | AK32: 0 | AL32: 1 | AM32: 0 | AN32: Baseflow | AO32: 1 | AP32: Clear | AQ32: 1 | AR32: None | AS32: 0 | AT32: 0 | AU32: 0 | AV32: 0 | AW32: 0 | AY32: 0 | AZ32: Absent | BA32: Absent | BB32: Absent | BC32: Absent | BD32: Absent | BE32: Absent | BF32: Absent | BG32: Present | BH32: Recorded | BI32: Spring Valley Creek | BJ32: 1 | BM32: Hiawatha | BN32: Hiawatha | BO32: 070400080205 | BP32: Spring Valley Creek | BQ32: 0704000802
A33: Dev: DBParsing_231030_v01.xlsm | B33: 6vfN6zwGtA1r1PDfqcNL | C33: 45559.681 | D33: 45559.431 | E33: 45559 | F33: 2024 | G33: 9 | H33: VQ9bNtzttGcXOEuaXrEAEYLfT103 | J33: -92.343748 | K33: 43.602327 | N33: 0 | P33: 1 | Q33: 120 | R33: 180 | U33: 7.5 | V33: 1 | W33: 0 | X33: 1 | Y33: 53 | Z33: 1 | AA33: 0 | AB33: 10 | AC33: River/Stream | AD33: None | AE33: 0 | AF33: 0 | AG33: 0 | AH33: 0 | AI33: 0 | AJ33: 0 | AK33: 0 | AL33: 1 | AM33: 0 | AN33: Baseflow | AO33: 1 | AP33: Clear | AQ33: 1 | AR33: None | AS33: 0 | AT33: 0 | AU33: 0 | AV33: 0 | AW33: 0 | AY33: 0 | AZ33: Absent | BA33: Absent | BB33: Absent | BC33: Absent | BD33: Absent | BE33: Absent | BF33: Absent | BG33: Present | BH33: Recorded | BI33: Etna Creek | BJ33: 1 | BM33: Hiawatha | BN33: Hiawatha | BO33: 070400080402 | BP33: Etna Creek-South Branch Root River | BQ33: 0704000804
A34: Dev: DBParsing_231030_v01.xlsm | B34: 8oC4USFto2fkxpH59LG7 | C34: 45548.604 | D34: 45548.354 | E34: 45548 | F34: 2024 | G34: 9 | H34: 80reiKTTqGYqqpgYAhPwqypFwak1 | J34: -92.055354 | K34: 44.092583 | M34: 2024-09-13 09:29:22.813119.jpg-0 | N34: 1 | P34: 1 | Q34: 180 | R34: 180 | U34: 8 | V34: 1 | W34: 0 | X34: 1 | Y34: 57 | Z34: 1 | AA34: 0 | AB34: 5 | AC34: River/Stream | AD34: None | AE34: 0 | AF34: 0 | AG34: 0 | AH34: 0 | AI34: 0 | AJ34: 0 | AK34: 0 | AL34: 1 | AM34: 0 | AN34: Mid-stage | AO34: 1 | AP34: Murky | AQ34: 1 | AR34: None | AS34: 0 | AT34: 0 | AU34: 0 | AV34: 0 | AW34: 0 | AX34: North Branch Whitewater is more stained than I thought it would be. Fairwater. | AY34: 1 | AZ34: Absent | BA34: Absent | BB34: Absent | BC34: Absent | BD34: Absent | BE34: Absent | BF34: Absent | BG34: Present | BH34: Recorded | BI34: North Fork Whitewater River | BJ34: 1 | BM34: Win Cres | BN34: Hiawatha | BO34: 070400030304 | BP34: Lower North Fork Whitewater River | BQ34: 0704000303
A35: Dev: DBParsing_231030_v01.xlsm | B35: hHKh8jH4j8IrBB3NZFjN | C35: 45547.695 | D35: 45547.445 | E35: 45547 | F35: 2024 | G35: 9 | H35: 7a7IFD1YT3aDXB8CbnSJjn1oLRC2 | I35: Isabelle Creek @ County Rd. EE | J35: -92.442779 | K35: 44.621391 | N35: 0 | P35: 1 | Q35: 120 | R35: 180 | U35: 8 | V35: 1 | W35: 100 | X35: 1 | Y35: 69 | Z35: 1 | AA35: 0 | AB35: 5 | AC35: River/Stream | AD35: None | AE35: 0 | AF35: 0 | AG35: 0 | AH35: 0 | AI35: 0 | AJ35: 0 | AK35: 0 | AL35: 1 | AM35: 0 | AN35: Baseflow | AO35: 1 | AP35: Murky | AQ35: 1 | AR35: None | AS35: 0 | AT35: 0 | AU35: 0 | AV35: 0 | AW35: 0 | AY35: 0 | AZ35: Absent | BA35: Absent | BB35: Absent | BC35: Absent | BD35: Absent | BE35: Absent | BF35: Absent | BG35: Present | BH35: Recorded | BI35: Isabelle Creek | BJ35: 1 | BM35: Kiap-TU-Wish | BN35: Unknown | BO35: 070400010701 | BP35: Isabelle Creek | BQ35: 0704000107
A36: Dev: DBParsing_231030_v01.xlsm | B36: TGHCciFGIqh4qNDTpWTq | C36: 45545.713 | D36: 45545.463 | E36: 45545 | F36: 2024 | G36: 9 | H36: 80reiKTTqGYqqpgYAhPwqypFwak1 | J36: -92.650029 | K36: 44.075179 | N36: 0 | P36: 0 | V36: 0 | X36: 1 | Y36: 59 | Z36: 1 | AA36: 0 | AB36: 5 | AC36: River/Stream | AD36: None | AE36: 0 | AF36: 0 | AG36: 0 | AH36: 0 | AI36: 0 | AJ36: 0 | AK36: 0 | AL36: 1 | AM36: 0 | AN36: Mid-stage | AO36: 1 | AP36: Murky | AQ36: 1 | AR36: None | AS36: 0 | AT36: 0 | AU36: 0 | AV36: 0 | AW36: 0 | AY36: 0 | AZ36: Absent | BA36: Absent | BB36: Absent | BC36: Absent | BD36: Absent | BE36: Absent | BF36: Absent | BG36: Present | BH36: Recorded | BI36: South Branch Middle Fork Zumbro River | BM36: Hiawatha | BN36: Hiawatha | BO36: 070400040205 | BP36: South Branch Middle Fork Zumbro River | BQ36: 0704000402
A37: Dev: DBParsing_231030_v01.xlsm | B37: nKBxSyTACqbPXHCVov9k | C37: 45543.702 | D37: 45543.452 | E37: 45543 | F37: 2024 | G37: 9 | H37: wOnBJTAV2CZK06CRnr5oUK45EDv1 | J37: -90.827354 | K37: 43.559228 | M37: 2024-09-08 11:50:44.402382.jpg-0 | N37: 1 | P37: 1 | Q37: 0 | R37: 30 | U37: 7.5 | V37: 1 | W37: 0 | X37: 1 | Y37: 56 | Z37: 1 | AA37: 0 | AB37: 2 | AC37: River/Stream | AD37: Bank Erosion | AE37: 0 | AF37: 1 | AG37: 0 | AH37: 0 | AI37: 0 | AJ37: 0 | AK37: 0 | AL37: 0 | AM37: 0 | AN37: Baseflow | AO37: 1 | AP37: Clear | AQ37: 1 | AR37: None | AS37: 0 | AT37: 0 | AU37: 0 | AV37: 0 | AW37: 0 | AX37: 2nd entry as first crashed. lots of brook trout. stream 51 at 9am | AY37: 1 | AZ37: Absent | BA37: Present | BB37: Absent | BC37: Absent | BD37: Absent | BE37: Absent | BF37: Absent | BG37: Absent | BH37: Recorded | BI37: Maple Dale | BK37: 1 | BL37: 1 | BM37: Coulee Region | BN37: US FWS | BO37: 070700060203 | BP37: Bishop Branch | BQ37: 0707000602
A38: Dev: DBParsing_231030_v01.xlsm | B38: gpr43ttOfpJXBgbUojU4 | C38: 45541.853 | D38: 45541.603 | E38: 45541 | F38: 2024 | G38: 9 | H38: 4etfOHFOLNgXiWPM6KYa0g0En8C2 | J38: -90.524037 | K38: 42.270183 | N38: 0 | P38: 1 | Q38: 120 | R38: 120 | U38: 7.5 | V38: 1 | W38: 0 | X38: 1 | Y38: 62 | Z38: 0 | AC38: River/Stream | AD38: None | AE38: 0 | AF38: 0 | AG38: 0 | AH38: 0 | AI38: 0 | AJ38: 0 | AK38: 0 | AL38: 1 | AM38: 0 | AN38: Baseflow | AO38: 1 | AP38: Clear | AQ38: 1 | AR38: None | AS38: 0 | AT38: 0 | AU38: 0 | AV38: 0 | AW38: 0 | AY38: 0 | AZ38: Absent | BA38: Absent | BB38: Absent | BC38: Absent | BD38: Absent | BE38: Absent | BF38: Absent | BG38: Present | BH38: Recorded | BI38: Mill Creek | BJ38: 1 | BM38: Spring Creeks | BN38: Spring Creeks | BO38: 070600050403 | BP38: Storybrook Hollow-Mill Creek | BQ38: 0706000504
A39: Dev: DBParsing_231030_v01.xlsm | B39: MjctNRhnki6R91OIE1k6 | C39: 45538.944 | D39: 45538.694 | E39: 45538 | F39: 2024 | G39: 9 | H39: mMKogvdinjOuckB5tkMQrxnYO852 | I39: Eau Galle River @ WI Hwy 29 | J39: -92.236399 | K39: 44.840174 | M39: 2024-09-03 17:40:03.476724.jpg-0 | N39: 1 | P39: 1 | Q39: 0 | R39: 60 | U39: 7 | V39: 1 | W39: 0 | X39: 1 | Y39: 67 | Z39: 1 | AA39: 0 | AB39: 2 | AC39: River/Stream | AD39: None | AE39: 0 | AF39: 0 | AG39: 0 | AH39: 0 | AI39: 0 | AJ39: 0 | AK39: 0 | AL39: 1 | AM39: 0 | AN39: Mid-stage | AO39: 1 | AP39: Clear | AQ39: 1 | AR39: None | AS39: 0 | AT39: 0 | AU39: 0 | AV39: 0 | AW39: 0 | AY39: 0 | AZ39: Absent | BA39: Absent | BB39: Absent | BC39: Absent | BD39: Absent | BE39: Absent | BF39: Absent | BG39: Present | BH39: Recorded | BI39: Burkhart Creek | BJ39: 1 | BK39: 1 | BL39: 1 | BM39: Kiap-TU-Wish | BN39: Kiap-TU-Wish | BO39: 070500051004 | BP39: Burkhart Creek-Eau Galle Creek | BQ39: 0705000510
A40: Dev: DBParsing_231030_v01.xlsm | B40: ntCQfYcOvqINI2kF431K | C40: 45538.818 | D40: 45538.568 | E40: 45538 | F40: 2024 | G40: 9 | H40: 80reiKTTqGYqqpgYAhPwqypFwak1 | J40: -92.649971 | K40: 44.075177 | N40: 0 | P40: 0 | V40: 0 | X40: 1 | Y40: 62 | Z40: 1 | AA40: 0 | AB40: 2 | AC40: River/Stream | AD40: None | AE40: 0 | AF40: 0 | AG40: 0 | AH40: 0 | AI40: 0 | AJ40: 0 | AK40: 0 | AL40: 1 | AM40: 0 | AN40: Mid-stage | AO40: 1 | AP40: Murky | AQ40: 1 | AR40: None | AS40: 0 | AT40: 0 | AU40: 0 | AV40: 0 | AW40: 0 | AX40: Zumbro is much clearer than last week. | AY40: 1 | AZ40: Absent | BA40: Absent | BB40: Absent | BC40: Absent | BD40: Absent | BE40: Absent | BF40: Absent | BG40: Present | BH40: Recorded | BI40: South Branch Middle Fork Zumbro River | BM40: Hiawatha | BN40: Hiawatha | BO40: 070400040205 | BP40: South Branch Middle Fork Zumbro River | BQ40: 0704000402
...

Sheet Use
A1: TU DARE Angler Science DB
B3: DRIFTLESS AREA OBSERVATIONS
B4: 2020-24 Observations (as of Oct 31st)
C5: Overall | D5: Number | E5: Percentage
C6: Target | D6: 2500 | E6: 1 | AH6: =20/90 -> 0.22222222
C7: Observations | D7: =TUDB!B4 -> 2320 | E7: =D7/D6 -> 0.928 | F7: =E7-0.05 -> 0.878
C8: Remaining | D8: =D6-D7 -> 180 | E8: =E6-E7 -> 0.072
B10: Participation
D11: Contributing Individuals | E11: 174
B12: Observations by Individuals
B13: Obs. | C13: 2020 | D13: 2021 | E13: 2022 | F13: 2023 | G13: 2024
B14: 0 | C14: {=FREQUENCY(F$50:F$171,$B$14:$B$22)} -> 111 | D14: {=FREQUENCY(G$50:G$171,$B$14:$B$22)} -> 89 | E14: {=FREQUENCY(H$50:H$171,$B$14:$B$22)} -> 61 | F14: {=FREQUENCY(I$50:I$171,$B$14:$B$22)} -> 41 | G14: {=FREQUENCY(J$50:J$171,$B$14:$B$22)} -> 85
B15: 1 | C15: 4 | D15: 2 | E15: 12 | F15: 19 | G15: 9 | S15: Observations per observer
B16: 5 | C16: 4 | D16: 10 | E16: 26 | F16: 26 | G16: 11
B17: 10 | C17: 1 | D17: 11 | E17: 10 | F17: 18 | G17: 7
B18: 15 | C18: 1 | D18: 3 | E18: 7 | F18: 5 | G18: 2
B19: 20 | C19: 0 | D19: 3 | E19: 2 | F19: 1 | G19: 1
B20: 25 | C20: 0 | D20: 2 | E20: 0 | F20: 2 | G20: 1
B21: 30 | C21: 0 | D21: 2 | E21: 1 | F21: 2 | G21: 1
B22: 35 | C22: 1 | D22: 0 | E22: 1 | F22: 0 | G22: 0
B23: 40+ | C23: 0 | D23: 0 | E23: 2 | F23: 8 | G23: 5
D26: Trout Streams | E26: =SUM(TU_DB[Trout Stream Flag]) -> 1945 | F26: =E26/(D7-60) -> 0.86061947
D27: Brook Trout Streams | E27: =SUM(TU_DB[Brook Trout Stream Flag]) -> 801 | F27: =E27/(D7-60) -> 0.35442478
B29: User Stats
B30: Year | C30: Active Observers | D30: Change from Previous Year | E30: New Observers | F30: Change from Previous Year | G30: Observations/ Observer | H30: Change from Previous Year | S30: Observations Reported | T30: Average | U30: 2020 | V30: 2021 | W30: 2022 | X30: 2023 | Y30: 2024
B31: 2019 | C31: {=TRANSPOSE(E47:J47)} -> 16 | D31: - | E31: 16 | F31: - | G31: =60/16 -> 3.75 | H31: - | S31: 0-1 | T31: =AVERAGE(U31:X31) -> 9.25 | U31: =C15 -> 4 | V31: =D15 -> 2 | W31: =E15 -> 12 | X31: =F15 -> 19 | Y31: =G15 -> 9
B32: 2020 | C32: 31 | D32: 0.98 | E32: {=TRANSPOSE(K47:O47)} -> 30 | F32: =(E32-E31)/E31 -> 0.875 | G32: {=TRANSPOSE(F48:J48)} -> 4.6451613 | H32: =(G32-G31)/G31 -> 0.23870968 | S32: 2-5 | T32: =AVERAGE(U32:X32) -> 16.5 | U32: =C16 -> 4 | V32: =D16 -> 10 | W32: =E16 -> 26 | X32: =F16 -> 26 | Y32: =G16 -> 11
B33: 2021 | C33: 54 | D33: =(C33-C32)/C32 -> 0.74193548 | E33: 43 | F33: =(E33-E32)/E32 -> 0.43333333 | G33: 7.537037 | H33: =(G33-G32)/G32 -> 0.62255658 | S33: 6-10 | T33: =AVERAGE(U33:X33) -> 10 | U33: =C17 -> 1 | V33: =D17 -> 11 | W33: =E17 -> 10 | X33: =F17 -> 18 | Y33: =G17 -> 7
B34: 2022 | C34: 61 | D34: =(C34-C33)/C33 -> 0.12962963 | E34: 33 | F34: =(E34-E33)/E33 -> -0.23255814 | G34: 7.5245902 | H34: =(G34-G33)/G33 -> -0.0016514279 | S34: 11-15 | T34: =AVERAGE(U34:X34) -> 4 | U34: =C18 -> 1 | V34: =D18 -> 3 | W34: =E18 -> 7 | X34: =F18 -> 5 | Y34: =G18 -> 2
B35: 2023 | C35: 81 | D35: =(C35-C34)/C34 -> 0.32786885 | E35: 39 | F35: =(E35-E34)/E34 -> 0.18181818 | G35: 9.962963 | H35: =(G35-G34)/G34 -> 0.3240539 | S35: 16-20 | T35: =AVERAGE(U35:X35) -> 1.5 | U35: =C19 -> 0 | V35: =D19 -> 3 | W35: =E19 -> 2 | X35: =F19 -> 1 | Y35: =G19 -> 1
B36: 2024 | C36: 37 | D36: =(C36-C35)/C35 -> -0.54320988 | E36: 13 | F36: =(E36-E31)/E31 -> -0.1875 | G36: 11.945946 | H36: =(G36-G31)/G31 -> 2.1855856 | S36: 21-25 | T36: =AVERAGE(U36:X36) -> 1 | U36: =C20 -> 0 | V36: =D20 -> 2 | W36: =E20 -> 0 | X36: =F20 -> 2 | Y36: =G20 -> 1
B37: 2025 | S37: 26-30 | T37: =AVERAGE(U37:X37) -> 1.25 | U37: =C21 -> 0 | V37: =D21 -> 2 | W37: =E21 -> 1 | X37: =F21 -> 2 | Y37: =G21 -> 1
B38: 2026 | S38: 31-35 | T38: =AVERAGE(U38:X38) -> 0.5 | U38: =C22 -> 1 | V38: =D22 -> 0 | W38: =E22 -> 1 | X38: =F22 -> 0 | Y38: =G22 -> 0
B39: 2027 | S39: 36-40+ | T39: =AVERAGE(U39:X39) -> 2.5 | U39: =C23 -> 0 | V39: =D23 -> 0 | W39: =E23 -> 2 | X39: =F23 -> 8 | Y39: =G23 -> 5
B40: 2028 | D40: =(C40-C35)/C35 -> -1 | F40: =(E40-E35)/E35 -> -1 | H40: =(G40-G35)/G35 -> -1 | T40: =SUM(T31:T39) -> 46.5 | U40: =SUM(U31:U39) -> 11 | V40: =SUM(V31:V39) -> 33 | W40: =SUM(W31:W39) -> 61 | X40: =SUM(X31:X39) -> 81 | Y40: =SUM(Y31:Y39) -> 37
B41: *Large turnover between 2019 to 2020 likely due to the change of app download from manual to through the Play Store/Apple Store
B46: DA User Data | K46: New Users | S46: App Use Stats
B47: Observers | D47: =COUNTIF(C50:C506,">"&0) -> 0 | E47: 16 | F47: =COUNTIF(F50:F506,">"&0) -> 31 | G47: =COUNTIF(G50:G506,">"&0) -> 54 | H47: =COUNTIF(H50:H506,">"&0) -> 61 | I47: =COUNTIF(I50:I506,">"&0) -> 81 | J47: =COUNTIF(J50:J506,">"&0) -> 37 | K47: =SUM(K50:K506) -> 30 | L47: =SUM(L50:L506) -> 43 | M47: =SUM(M50:M506) -> 33 | N47: =SUM(N50:N506) -> 39 | O47: =SUM(O50:O506) -> 13
B48: Obsvns/obsvr | D48: =IFERROR(SUM(C50:C506)/D47,0) -> 0 | E48: =60/E47 -> 3.75 | F48: =IFERROR(SUM(F50:F506)/F47,0) -> 4.6451613 | G48: =IFERROR(SUM(G50:G506)/G47,0) -> 7.537037 | H48: =IFERROR(SUM(H50:H506)/H47,0) -> 7.5245902 | I48: =IFERROR(SUM(I50:I506)/I47,0) -> 9.962963 | J48: =IFERROR(SUM(J50:J506)/J47,0) -> 11.945946 | S48: Year | T48: Observa-tions | U48: Observ. Water Source | V48: 5n1 Test Strip | W48: 2n1 Test Strip | X48: Phosphorus Test Strip | Y48: Water Temp. | Z48: Stream Disturb-ances | AA48: Current Conditions
B49: Obsvr ID | C49: Affilliation | D49: Sum | E49: 2019 | F49: 2020 | G49: 2021 | H49: 2022 | I49: 2023 | J49: 2024 | K49: 2020 | L49: 2021 | M49: 2022 | N49: 2023 | O49: 2024 | S49: Analyses per observation
...

Sheet ALK
A1: TU DARE Angler Science DB
B2: Water Analysis | C2: Alkalinity
B3: Download | C3: =TUDB!B3 -> 45580
B5: Overview Stats
B6: Alkalinity [ppm CaCO3] | C6: Observations | D6: % Total Obs. | E6: Cum. % | F6: 2019 | G6: 2020 | H6: 2021 | I6: 2022 | J6: 2023 | K6: 2024
B7: 0 | C7: =COUNTIFS(TU_DB[ALK Bin (ppm)],B7) -> 184 | D7: =C7/$C$13 -> 0.091862207 | E7: =D7 -> 0.091862207 | F7: =COUNTIFS(TU_DB[[ALK Bin (ppm)]:[ALK Bin (ppm)]],$B7,TU_DB[[Year]:[Year]],F$6) -> 0 | G7: =COUNTIFS(TU_DB[[ALK Bin (ppm)]:[ALK Bin (ppm)]],$B7,TU_DB[[Year]:[Year]],G$6) -> 16 | H7: =COUNTIFS(TU_DB[[ALK Bin (ppm)]:[ALK Bin (ppm)]],$B7,TU_DB[[Year]:[Year]],H$6) -> 44 | I7: =COUNTIFS(TU_DB[[ALK Bin (ppm)]:[ALK Bin (ppm)]],$B7,TU_DB[[Year]:[Year]],I$6) -> 41 | J7: =COUNTIFS(TU_DB[[ALK Bin (ppm)]:[ALK Bin (ppm)]],$B7,TU_DB[[Year]:[Year]],J$6) -> 58 | K7: =COUNTIFS(TU_DB[[ALK Bin (ppm)]:[ALK Bin (ppm)]],$B7,TU_DB[[Year]:[Year]],K$6) -> 25
B8: 40 | C8: =COUNTIFS(TU_DB[ALK Bin (ppm)],B8) -> 203 | D8: =C8/$C$13 -> 0.10134798 | E8: =D8+E7 -> 0.19321018 | F8: =COUNTIFS(TU_DB[[ALK Bin (ppm)]:[ALK Bin (ppm)]],$B8,TU_DB[[Year]:[Year]],F$6) -> 0 | G8: =COUNTIFS(TU_DB[[ALK Bin (ppm)]:[ALK Bin (ppm)]],$B8,TU_DB[[Year]:[Year]],G$6) -> 6 | H8: =COUNTIFS(TU_DB[[ALK Bin (ppm)]:[ALK Bin (ppm)]],$B8,TU_DB[[Year]:[Year]],H$6) -> 14 | I8: =COUNTIFS(TU_DB[[ALK Bin (ppm)]:[ALK Bin (ppm)]],$B8,TU_DB[[Year]:[Year]],I$6) -> 36 | J8: =COUNTIFS(TU_DB[[ALK Bin (ppm)]:[ALK Bin (ppm)]],$B8,TU_DB[[Year]:[Year]],J$6) -> 106 | K8: =COUNTIFS(TU_DB[[ALK Bin (ppm)]:[ALK Bin (ppm)]],$B8,TU_DB[[Year]:[Year]],K$6) -> 41
B9: 80 | C9: =COUNTIFS(TU_DB[ALK Bin (ppm)],B9) -> 405 | D9: =C9/$C$13 -> 0.2021967 | E9: =D9+E8 -> 0.39540689 | F9: =COUNTIFS(TU_DB[[ALK Bin (ppm)]:[ALK Bin (ppm)]],$B9,TU_DB[[Year]:[Year]],F$6) -> 0 | G9: =COUNTIFS(TU_DB[[ALK Bin (ppm)]:[ALK Bin (ppm)]],$B9,TU_DB[[Year]:[Year]],G$6) -> 15 | H9: =COUNTIFS(TU_DB[[ALK Bin (ppm)]:[ALK Bin (ppm)]],$B9,TU_DB[[Year]:[Year]],H$6) -> 78 | I9: =COUNTIFS(TU_DB[[ALK Bin (ppm)]:[ALK Bin (ppm)]],$B9,TU_DB[[Year]:[Year]],I$6) -> 91 | J9: =COUNTIFS(TU_DB[[ALK Bin (ppm)]:[ALK Bin (ppm)]],$B9,TU_DB[[Year]:[Year]],J$6) -> 126 | K9: =COUNTIFS(TU_DB[[ALK Bin (ppm)]:[ALK Bin (ppm)]],$B9,TU_DB[[Year]:[Year]],K$6) -> 95
B10: 120 | C10: =COUNTIFS(TU_DB[ALK Bin (ppm)],B10) -> 290 | D10: =C10/$C$13 -> 0.14478283 | E10: =D10+E9 -> 0.54018972 | F10: =COUNTIFS(TU_DB[[ALK Bin (ppm)]:[ALK Bin (ppm)]],$B10,TU_DB[[Year]:[Year]],F$6) -> 0 | G10: =COUNTIFS(TU_DB[[ALK Bin (ppm)]:[ALK Bin (ppm)]],$B10,TU_DB[[Year]:[Year]],G$6) -> 20 | H10: =COUNTIFS(TU_DB[[ALK Bin (ppm)]:[ALK Bin (ppm)]],$B10,TU_DB[[Year]:[Year]],H$6) -> 54 | I10: =COUNTIFS(TU_DB[[ALK Bin (ppm)]:[ALK Bin (ppm)]],$B10,TU_DB[[Year]:[Year]],I$6) -> 61 | J10: =COUNTIFS(TU_DB[[ALK Bin (ppm)]:[ALK Bin (ppm)]],$B10,TU_DB[[Year]:[Year]],J$6) -> 98 | K10: =COUNTIFS(TU_DB[[ALK Bin (ppm)]:[ALK Bin (ppm)]],$B10,TU_DB[[Year]:[Year]],K$6) -> 57
B11: 180 | C11: =COUNTIFS(TU_DB[ALK Bin (ppm)],B11) -> 897 | D11: =C11/$C$13 -> 0.44782826 | E11: =D11+E10 -> 0.98801797 | F11: =COUNTIFS(TU_DB[[ALK Bin (ppm)]:[ALK Bin (ppm)]],$B11,TU_DB[[Year]:[Year]],F$6) -> 4 | G11: =COUNTIFS(TU_DB[[ALK Bin (ppm)]:[ALK Bin (ppm)]],$B11,TU_DB[[Year]:[Year]],G$6) -> 41 | H11: =COUNTIFS(TU_DB[[ALK Bin (ppm)]:[ALK Bin (ppm)]],$B11,TU_DB[[Year]:[Year]],H$6) -> 168 | I11: =COUNTIFS(TU_DB[[ALK Bin (ppm)]:[ALK Bin (ppm)]],$B11,TU_DB[[Year]:[Year]],I$6) -> 188 | J11: =COUNTIFS(TU_DB[[ALK Bin (ppm)]:[ALK Bin (ppm)]],$B11,TU_DB[[Year]:[Year]],J$6) -> 322 | K11: =COUNTIFS(TU_DB[[ALK Bin (ppm)]:[ALK Bin (ppm)]],$B11,TU_DB[[Year]:[Year]],K$6) -> 174
B12: 240 | C12: =COUNTIFS(TU_DB[ALK Bin (ppm)],B12) -> 24 | D12: =C12/$C$13 -> 0.011982027 | E12: =D12+E11 -> 1 | F12: =COUNTIFS(TU_DB[[ALK Bin (ppm)]:[ALK Bin (ppm)]],$B12,TU_DB[[Year]:[Year]],F$6) -> 0 | G12: =COUNTIFS(TU_DB[[ALK Bin (ppm)]:[ALK Bin (ppm)]],$B12,TU_DB[[Year]:[Year]],G$6) -> 10 | H12: =COUNTIFS(TU_DB[[ALK Bin (ppm)]:[ALK Bin (ppm)]],$B12,TU_DB[[Year]:[Year]],H$6) -> 3 | I12: =COUNTIFS(TU_DB[[ALK Bin (ppm)]:[ALK Bin (ppm)]],$B12,TU_DB[[Year]:[Year]],I$6) -> 2 | J12: =COUNTIFS(TU_DB[[ALK Bin (ppm)]:[ALK Bin (ppm)]],$B12,TU_DB[[Year]:[Year]],J$6) -> 4 | K12: =COUNTIFS(TU_DB[[ALK Bin (ppm)]:[ALK Bin (ppm)]],$B12,TU_DB[[Year]:[Year]],K$6) -> 5
B13: Total | C13: =SUM(C7:C12) -> 2003 | F13: =SUM(F7:F12) -> 4 | G13: =SUM(G7:G12) -> 108 | H13: =SUM(H7:H12) -> 361 | I13: =SUM(I7:I12) -> 419 | J13: =SUM(J7:J12) -> 714 | K13: =SUM(K7:K12) -> 397
B17: Weather Conditions
C18: Alkalinity [ppm CaCO3] | K18: Table Labels
B19: Weather Conditions | C19: 0 | D19: 40 | E19: 80 | F19: 120 | G19: 180 | H19: 240 | I19: Sum | J19: % Total
B20: Local Thunderstorm | C20: =COUNTIFS(TU_DB[[ALK Bin (ppm)]:[ALK Bin (ppm)]],C$19,TU_DB[[Weather]:[Weather]],$B20) -> 7 | D20: =COUNTIFS(TU_DB[[ALK Bin (ppm)]:[ALK Bin (ppm)]],D$19,TU_DB[[Weather]:[Weather]],$B20) -> 7 | E20: =COUNTIFS(TU_DB[[ALK Bin (ppm)]:[ALK Bin (ppm)]],E$19,TU_DB[[Weather]:[Weather]],$B20) -> 25 | F20: =COUNTIFS(TU_DB[[ALK Bin (ppm)]:[ALK Bin (ppm)]],F$19,TU_DB[[Weather]:[Weather]],$B20) -> 7 | G20: =COUNTIFS(TU_DB[[ALK Bin (ppm)]:[ALK Bin (ppm)]],G$19,TU_DB[[Weather]:[Weather]],$B20) -> 37 | H20: =COUNTIFS(TU_DB[[ALK Bin (ppm)]:[ALK Bin (ppm)]],H$19,TU_DB[[Weather]:[Weather]],$B20) -> 1 | I20: =SUM(C20:H20) -> 84 | J20: =SUM(I20)/SUM($I$20:$I$25) -> 0.047457627 | K20: LT
B21: Regional Rainfall | C21: =COUNTIFS(TU_DB[[ALK Bin (ppm)]:[ALK Bin (ppm)]],C$19,TU_DB[[Weather]:[Weather]],$B21) -> 24 | D21: =COUNTIFS(TU_DB[[ALK Bin (ppm)]:[ALK Bin (ppm)]],D$19,TU_DB[[Weather]:[Weather]],$B21) -> 39 | E21: =COUNTIFS(TU_DB[[ALK Bin (ppm)]:[ALK Bin (ppm)]],E$19,TU_DB[[Weather]:[Weather]],$B21) -> 51 | F21: =COUNTIFS(TU_DB[[ALK Bin (ppm)]:[ALK Bin (ppm)]],F$19,TU_DB[[Weather]:[Weather]],$B21) -> 40 | G21: =COUNTIFS(TU_DB[[ALK Bin (ppm)]:[ALK Bin (ppm)]],G$19,TU_DB[[Weather]:[Weather]],$B21) -> 89 | H21: =COUNTIFS(TU_DB[[ALK Bin (ppm)]:[ALK Bin (ppm)]],H$19,TU_DB[[Weather]:[Weather]],$B21) -> 2 | I21: =SUM(C21:H21) -> 245 | J21: =SUM(I21)/SUM($I$20:$I$25) -> 0.13841808 | K21: RR
B22: Regional Rainfall,Local Thunderstorm | C22: =COUNTIFS(TU_DB[[ALK Bin (ppm)]:[ALK Bin (ppm)]],C$19,TU_DB[[Weather]:[Weather]],$B22) -> 0 | D22: =COUNTIFS(TU_DB[[ALK Bin (ppm)]:[ALK Bin (ppm)]],D$19,TU_DB[[Weather]:[Weather]],$B22) -> 1 | E22: =COUNTIFS(TU_DB[[ALK Bin (ppm)]:[ALK Bin (ppm)]],E$19,TU_DB[[Weather]:[Weather]],$B22) -> 5 | F22: =COUNTIFS(TU_DB[[ALK Bin (ppm)]:[ALK Bin (ppm)]],F$19,TU_DB[[Weather]:[Weather]],$B22) -> 1 | G22: =COUNTIFS(TU_DB[[ALK Bin (ppm)]:[ALK Bin (ppm)]],G$19,TU_DB[[Weather]:[Weather]],$B22) -> 3 | H22: =COUNTIFS(TU_DB[[ALK Bin (ppm)]:[ALK Bin (ppm)]],H$19,TU_DB[[Weather]:[Weather]],$B22) -> 0 | I22: =SUM(C22:H22) -> 10 | J22: =SUM(I22)/SUM($I$20:$I$25) -> 0.0056497175 | K22: RR, LT
B23: Regional Rainfall,Warmth Causing Snowmelt | C23: =COUNTIFS(TU_DB[[ALK Bin (ppm)]:[ALK Bin (ppm)]],C$19,TU_DB[[Weather]:[Weather]],$B23) -> 0 | D23: =COUNTIFS(TU_DB[[ALK Bin (ppm)]:[ALK Bin (ppm)]],D$19,TU_DB[[Weather]:[Weather]],$B23) -> 0 | E23: =COUNTIFS(TU_DB[[ALK Bin (ppm)]:[ALK Bin (ppm)]],E$19,TU_DB[[Weather]:[Weather]],$B23) -> 0 | F23: =COUNTIFS(TU_DB[[ALK Bin (ppm)]:[ALK Bin (ppm)]],F$19,TU_DB[[Weather]:[Weather]],$B23) -> 2 | G23: =COUNTIFS(TU_DB[[ALK Bin (ppm)]:[ALK Bin (ppm)]],G$19,TU_DB[[Weather]:[Weather]],$B23) -> 2 | H23: =COUNTIFS(TU_DB[[ALK Bin (ppm)]:[ALK Bin (ppm)]],H$19,TU_DB[[Weather]:[Weather]],$B23) -> 1 | I23: =SUM(C23:H23) -> 5 | J23: =SUM(I23)/SUM($I$20:$I$25) -> 0.0028248588 | K23: RR, SM
B24: Warmth Causing Snowmelt | C24: =COUNTIFS(TU_DB[[ALK Bin (ppm)]:[ALK Bin (ppm)]],C$19,TU_DB[[Weather]:[Weather]],$B24) -> 2 | D24: =COUNTIFS(TU_DB[[ALK Bin (ppm)]:[ALK Bin (ppm)]],D$19,TU_DB[[Weather]:[Weather]],$B24) -> 2 | E24: =COUNTIFS(TU_DB[[ALK Bin (ppm)]:[ALK Bin (ppm)]],E$19,TU_DB[[Weather]:[Weather]],$B24) -> 4 | F24: =COUNTIFS(TU_DB[[ALK Bin (ppm)]:[ALK Bin (ppm)]],F$19,TU_DB[[Weather]:[Weather]],$B24) -> 0 | G24: =COUNTIFS(TU_DB[[ALK Bin (ppm)]:[ALK Bin (ppm)]],G$19,TU_DB[[Weather]:[Weather]],$B24) -> 8 | H24: =COUNTIFS(TU_DB[[ALK Bin (ppm)]:[ALK Bin (ppm)]],H$19,TU_DB[[Weather]:[Weather]],$B24) -> 4 | I24: =SUM(C24:H24) -> 20 | J24: =SUM(I24)/SUM($I$20:$I$25) -> 0.011299435 | K24: SM
B25: None | C25: =COUNTIFS(TU_DB[[ALK Bin (ppm)]:[ALK Bin (ppm)]],C$19,TU_DB[[Weather]:[Weather]],$B25) -> 122 | D25: =COUNTIFS(TU_DB[[ALK Bin (ppm)]:[ALK Bin (ppm)]],D$19,TU_DB[[Weather]:[Weather]],$B25) -> 130 | E25: =COUNTIFS(TU_DB[[ALK Bin (ppm)]:[ALK Bin (ppm)]],E$19,TU_DB[[Weather]:[Weather]],$B25) -> 279 | F25: =COUNTIFS(TU_DB[[ALK Bin (ppm)]:[ALK Bin (ppm)]],F$19,TU_DB[[Weather]:[Weather]],$B25) -> 200 | G25: =COUNTIFS(TU_DB[[ALK Bin (ppm)]:[ALK Bin (ppm)]],G$19,TU_DB[[Weather]:[Weather]],$B25) -> 661 | H25: =COUNTIFS(TU_DB[[ALK Bin (ppm)]:[ALK Bin (ppm)]],H$19,TU_DB[[Weather]:[Weather]],$B25) -> 14 | I25: =SUM(C25:H25) -> 1406 | J25: =SUM(I25)/SUM($I$20:$I$25) -> 0.79435028 | K25: None
B26: Total | C26: =SUM(C20:C25) -> 155 | D26: =SUM(D20:D25) -> 179 | E26: =SUM(E20:E25) -> 364 | F26: =SUM(F20:F25) -> 250 | G26: =SUM(G20:G25) -> 800 | H26: =SUM(H20:H25) -> 22 | I26: =SUM(I20:I25) -> 1770
B28: Water Level
C29: Alkalinity [ppm CaCO3]
B30: Water Level | C30: 0 | D30: 40 | E30: 80 | F30: 120 | G30: 180 | H30: 240 | I30: Sum | J30: % Total
B31: Baseflow | C31: =COUNTIFS(TU_DB[[ALK Bin (ppm)]:[ALK Bin (ppm)]],C$19,TU_DB[[Water Level]:[Water Level]],$B31) -> 112 | D31: =COUNTIFS(TU_DB[[ALK Bin (ppm)]:[ALK Bin (ppm)]],D$19,TU_DB[[Water Level]:[Water Level]],$B31) -> 132 | E31: =COUNTIFS(TU_DB[[ALK Bin (ppm)]:[ALK Bin (ppm)]],E$19,TU_DB[[Water Level]:[Water Level]],$B31) -> 252 | F31: =COUNTIFS(TU_DB[[ALK Bin (ppm)]:[ALK Bin (ppm)]],F$19,TU_DB[[Water Level]:[Water Level]],$B31) -> 206 | G31: =COUNTIFS(TU_DB[[ALK Bin (ppm)]:[ALK Bin (ppm)]],G$19,TU_DB[[Water Level]:[Water Level]],$B31) -> 655 | H31: =COUNTIFS(TU_DB[[ALK Bin (ppm)]:[ALK Bin (ppm)]],H$19,TU_DB[[Water Level]:[Water Level]],$B31) -> 16 | I31: =SUM(C31:H31) -> 1373 | J31: =SUM(I31)/SUM($I$31:$I$34) -> 0.75814467
B32: Mid-Stage | C32: =COUNTIFS(TU_DB[[ALK Bin (ppm)]:[ALK Bin (ppm)]],C$19,TU_DB[[Water Level]:[Water Level]],$B32) -> 35 | D32: =COUNTIFS(TU_DB[[ALK Bin (ppm)]:[ALK Bin (ppm)]],D$19,TU_DB[[Water Level]:[Water Level]],$B32) -> 47 | E32: =COUNTIFS(TU_DB[[ALK Bin (ppm)]:[ALK Bin (ppm)]],E$19,TU_DB[[Water Level]:[Water Level]],$B32) -> 90 | F32: =COUNTIFS(TU_DB[[ALK Bin (ppm)]:[ALK Bin (ppm)]],F$19,TU_DB[[Water Level]:[Water Level]],$B32) -> 34 | G32: =COUNTIFS(TU_DB[[ALK Bin (ppm)]:[ALK Bin (ppm)]],G$19,TU_DB[[Water Level]:[Water Level]],$B32) -> 145 | H32: =COUNTIFS(TU_DB[[ALK Bin (ppm)]:[ALK Bin (ppm)]],H$19,TU_DB[[Water Level]:[Water Level]],$B32) -> 6 | I32: =SUM(C32:H32) -> 357 | J32: =SUM(I32)/SUM($I$31:$I$34) -> 0.19712866
B33: Bankfull Stage | C33: =COUNTIFS(TU_DB[[ALK Bin (ppm)]:[ALK Bin (ppm)]],C$19,TU_DB[[Water Level]:[Water Level]],$B33) -> 5 | D33: =COUNTIFS(TU_DB[[ALK Bin (ppm)]:[ALK Bin (ppm)]],D$19,TU_DB[[Water Level]:[Water Level]],$B33) -> 3 | E33: =COUNTIFS(TU_DB[[ALK Bin (ppm)]:[ALK Bin (ppm)]],E$19,TU_DB[[Water Level]:[Water Level]],$B33) -> 24 | F33: =COUNTIFS(TU_DB[[ALK Bin (ppm)]:[ALK Bin (ppm)]],F$19,TU_DB[[Water Level]:[Water Level]],$B33) -> 19 | G33: =COUNTIFS(TU_DB[[ALK Bin (ppm)]:[ALK Bin (ppm)]],G$19,TU_DB[[Water Level]:[Water Level]],$B33) -> 24 | H33: =COUNTIFS(TU_DB[[ALK Bin (ppm)]:[ALK Bin (ppm)]],H$19,TU_DB[[Water Level]:[Water Level]],$B33) -> 0 | I33: =SUM(C33:H33) -> 75 | J33: =SUM(I33)/SUM($I$31:$I$34) -> 0.041413584
B34: Overbank Flooding | C34: 1 | D34: 1 | E34: 1 | F34: 1 | G34: 2 | H34: 0 | I34: 6 | J34: =SUM(I34)/SUM($I$31:$I$34) -> 0.0033130867
B35: Total | C35: =SUM(C31:C34) -> 153 | D35: =SUM(D31:D34) -> 183 | E35: =SUM(E31:E34) -> 367 | F35: =SUM(F31:F34) -> 260 | G35: =SUM(G31:G34) -> 826 | H35: =SUM(H31:H34) -> 22 | I35: =SUM(I31:I34) -> 1811
B44: Water Clarity
C45: Alkalinity [ppm CaCO3]
B46: Water Clarity | C46: 0 | D46: 40 | E46: 80 | F46: 120 | G46: 180 | H46: 240 | I46: Sum | J46: % Total
B47: Clear | C47: =COUNTIFS(TU_DB[[ALK Bin (ppm)]:[ALK Bin (ppm)]],C$19,TU_DB[[Clarity]:[Clarity]],$B47) -> 117 | D47: =COUNTIFS(TU_DB[[ALK Bin (ppm)]:[ALK Bin (ppm)]],D$19,TU_DB[[Clarity]:[Clarity]],$B47) -> 125 | E47: =COUNTIFS(TU_DB[[ALK Bin (ppm)]:[ALK Bin (ppm)]],E$19,TU_DB[[Clarity]:[Clarity]],$B47) -> 279 | F47: =COUNTIFS(TU_DB[[ALK Bin (ppm)]:[ALK Bin (ppm)]],F$19,TU_DB[[Clarity]:[Clarity]],$B47) -> 204 | G47: =COUNTIFS(TU_DB[[ALK Bin (ppm)]:[ALK Bin (ppm)]],G$19,TU_DB[[Clarity]:[Clarity]],$B47) -> 664 | H47: =COUNTIFS(TU_DB[[ALK Bin (ppm)]:[ALK Bin (ppm)]],H$19,TU_DB[[Clarity]:[Clarity]],$B47) -> 17 | I47: =SUM(C47:H47) -> 1406 | J47: =SUM(I47)/SUM($I$47:$I$49) -> 0.77125617
B48: Muddy | C48: =COUNTIFS(TU_DB[[ALK Bin (ppm)]:[ALK Bin (ppm)]],C$19,TU_DB[[Clarity]:[Clarity]],$B48) -> 7 | D48: =COUNTIFS(TU_DB[[ALK Bin (ppm)]:[ALK Bin (ppm)]],D$19,TU_DB[[Clarity]:[Clarity]],$B48) -> 8 | E48: =COUNTIFS(TU_DB[[ALK Bin (ppm)]:[ALK Bin (ppm)]],E$19,TU_DB[[Clarity]:[Clarity]],$B48) -> 31 | F48: =COUNTIFS(TU_DB[[ALK Bin (ppm)]:[ALK Bin (ppm)]],F$19,TU_DB[[Clarity]:[Clarity]],$B48) -> 14 | G48: =COUNTIFS(TU_DB[[ALK Bin (ppm)]:[ALK Bin (ppm)]],G$19,TU_DB[[Clarity]:[Clarity]],$B48) -> 26 | H48: =COUNTIFS(TU_DB[[ALK Bin (ppm)]:[ALK Bin (ppm)]],H$19,TU_DB[[Clarity]:[Clarity]],$B48) -> 1 | I48: =SUM(C48:H48) -> 87 | J48: =SUM(I48)/SUM($I$47:$I$49) -> 0.047723533
B49: Murky | C49: =COUNTIFS(TU_DB[[ALK Bin (ppm)]:[ALK Bin (ppm)]],C$19,TU_DB[[Clarity]:[Clarity]],$B49) -> 32 | D49: =COUNTIFS(TU_DB[[ALK Bin (ppm)]:[ALK Bin (ppm)]],D$19,TU_DB[[Clarity]:[Clarity]],$B49) -> 49 | E49: =COUNTIFS(TU_DB[[ALK Bin (ppm)]:[ALK Bin (ppm)]],E$19,TU_DB[[Clarity]:[Clarity]],$B49) -> 66 | F49: =COUNTIFS(TU_DB[[ALK Bin (ppm)]:[ALK Bin (ppm)]],F$19,TU_DB[[Clarity]:[Clarity]],$B49) -> 43 | G49: =COUNTIFS(TU_DB[[ALK Bin (ppm)]:[ALK Bin (ppm)]],G$19,TU_DB[[Clarity]:[Clarity]],$B49) -> 136 | H49: =COUNTIFS(TU_DB[[ALK Bin (ppm)]:[ALK Bin (ppm)]],H$19,TU_DB[[Clarity]:[Clarity]],$B49) -> 4 | I49: =SUM(C49:H49) -> 330 | J49: =SUM(I49)/SUM($I$47:$I$49) -> 0.1810203
B50: Total | C50: =SUM(C47:C49) -> 156 | D50: =SUM(D47:D49) -> 182 | E50: =SUM(E47:E49) -> 376 | F50: =SUM(F47:F49) -> 261 | G50: =SUM(G47:G49) -> 826 | H50: =SUM(H47:H49) -> 22 | I50: =SUM(I47:I49) -> 1823
B61: Monitoring Stations
C62: Alkalinity [ppm CaCO3] | M62: Station to Plot | N62: Kiat-TU-Wish
B63: Monitoring Site | C63: 0 | D63: 40 | E63: 80 | F63: 120 | G63: 180 | H63: 240 | I63: Sum | J63: % Total
...

Sheet HRD
A1: TU DARE Angler Science DB
B2: Water Analysis | C2: Hardness
B3: Download | C3: =TUDB!B3 -> 45580
B5: Overview Stats
B6: Hardness [ppm CaCO3] | C6: Observations | D6: % Total Obs. | E6: Cum. % | F6: 2019 | G6: 2020 | H6: 2021 | I6: 2022 | J6: 2023 | K6: 2024
B7: 0 | C7: =COUNTIFS(TU_DB[HRD Bin (ppm)],B7) -> 122 | D7: =C7/$C$12 -> 0.060908637 | E7: =D7 -> 0.060908637 | F7: =COUNTIFS(TU_DB[[HRD Bin (ppm)]:[HRD Bin (ppm)]],$B7,TU_DB[[Year]:[Year]],F$6) -> 0 | G7: =COUNTIFS(TU_DB[[HRD Bin (ppm)]:[HRD Bin (ppm)]],$B7,TU_DB[[Year]:[Year]],G$6) -> 8 | H7: =COUNTIFS(TU_DB[[HRD Bin (ppm)]:[HRD Bin (ppm)]],$B7,TU_DB[[Year]:[Year]],H$6) -> 20 | I7: =COUNTIFS(TU_DB[[HRD Bin (ppm)]:[HRD Bin (ppm)]],$B7,TU_DB[[Year]:[Year]],I$6) -> 24 | J7: =COUNTIFS(TU_DB[[HRD Bin (ppm)]:[HRD Bin (ppm)]],$B7,TU_DB[[Year]:[Year]],J$6) -> 39 | K7: =COUNTIFS(TU_DB[[HRD Bin (ppm)]:[HRD Bin (ppm)]],$B7,TU_DB[[Year]:[Year]],K$6) -> 31
B8: 30 | C8: =COUNTIFS(TU_DB[HRD Bin (ppm)],B8) -> 139 | D8: =C8/$C$12 -> 0.069395906 | E8: =D8+E7 -> 0.13030454 | F8: =COUNTIFS(TU_DB[[HRD Bin (ppm)]:[HRD Bin (ppm)]],$B8,TU_DB[[Year]:[Year]],F$6) -> 0 | G8: =COUNTIFS(TU_DB[[HRD Bin (ppm)]:[HRD Bin (ppm)]],$B8,TU_DB[[Year]:[Year]],G$6) -> 18 | H8: =COUNTIFS(TU_DB[[HRD Bin (ppm)]:[HRD Bin (ppm)]],$B8,TU_DB[[Year]:[Year]],H$6) -> 28 | I8: =COUNTIFS(TU_DB[[HRD Bin (ppm)]:[HRD Bin (ppm)]],$B8,TU_DB[[Year]:[Year]],I$6) -> 31 | J8: =COUNTIFS(TU_DB[[HRD Bin (ppm)]:[HRD Bin (ppm)]],$B8,TU_DB[[Year]:[Year]],J$6) -> 46 | K8: =COUNTIFS(TU_DB[[HRD Bin (ppm)]:[HRD Bin (ppm)]],$B8,TU_DB[[Year]:[Year]],K$6) -> 16
B9: 60 | C9: =COUNTIFS(TU_DB[HRD Bin (ppm)],B9) -> 206 | D9: =C9/$C$12 -> 0.10284573 | E9: =D9+E8 -> 0.23315027 | F9: =COUNTIFS(TU_DB[[HRD Bin (ppm)]:[HRD Bin (ppm)]],$B9,TU_DB[[Year]:[Year]],F$6) -> 0 | G9: =COUNTIFS(TU_DB[[HRD Bin (ppm)]:[HRD Bin (ppm)]],$B9,TU_DB[[Year]:[Year]],G$6) -> 23 | H9: =COUNTIFS(TU_DB[[HRD Bin (ppm)]:[HRD Bin (ppm)]],$B9,TU_DB[[Year]:[Year]],H$6) -> 35 | I9: =COUNTIFS(TU_DB[[HRD Bin (ppm)]:[HRD Bin (ppm)]],$B9,TU_DB[[Year]:[Year]],I$6) -> 31 | J9: =COUNTIFS(TU_DB[[HRD Bin (ppm)]:[HRD Bin (ppm)]],$B9,TU_DB[[Year]:[Year]],J$6) -> 80 | K9: =COUNTIFS(TU_DB[[HRD Bin (ppm)]:[HRD Bin (ppm)]],$B9,TU_DB[[Year]:[Year]],K$6) -> 37
B10: 120 | C10: =COUNTIFS(TU_DB[HRD Bin (ppm)],B10) -> 674 | D10: =C10/$C$12 -> 0.33649526 | E10: =D10+E9 -> 0.56964553 | F10: =COUNTIFS(TU_DB[[HRD Bin (ppm)]:[HRD Bin (ppm)]],$B10,TU_DB[[Year]:[Year]],F$6) -> 1 | G10: =COUNTIFS(TU_DB[[HRD Bin (ppm)]:[HRD Bin (ppm)]],$B10,TU_DB[[Year]:[Year]],G$6) -> 35 | H10: =COUNTIFS(TU_DB[[HRD Bin (ppm)]:[HRD Bin (ppm)]],$B10,TU_DB[[Year]:[Year]],H$6) -> 139 | I10: =COUNTIFS(TU_DB[[HRD Bin (ppm)]:[HRD Bin (ppm)]],$B10,TU_DB[[Year]:[Year]],I$6) -> 140 | J10: =COUNTIFS(TU_DB[[HRD Bin (ppm)]:[HRD Bin (ppm)]],$B10,TU_DB[[Year]:[Year]],J$6) -> 226 | K10: =COUNTIFS(TU_DB[[HRD Bin (ppm)]:[HRD Bin (ppm)]],$B10,TU_DB[[Year]:[Year]],K$6) -> 133
B11: 180 | C11: =COUNTIFS(TU_DB[HRD Bin (ppm)],B11) -> 862 | D11: =C11/$C$12 -> 0.43035447 | E11: =D11+E10 -> 1 | F11: =COUNTIFS(TU_DB[[HRD Bin (ppm)]:[HRD Bin (ppm)]],$B11,TU_DB[[Year]:[Year]],F$6) -> 3 | G11: =COUNTIFS(TU_DB[[HRD Bin (ppm)]:[HRD Bin (ppm)]],$B11,TU_DB[[Year]:[Year]],G$6) -> 24 | H11: =COUNTIFS(TU_DB[[HRD Bin (ppm)]:[HRD Bin (ppm)]],$B11,TU_DB[[Year]:[Year]],H$6) -> 139 | I11: =COUNTIFS(TU_DB[[HRD Bin (ppm)]:[HRD Bin (ppm)]],$B11,TU_DB[[Year]:[Year]],I$6) -> 193 | J11: =COUNTIFS(TU_DB[[HRD Bin (ppm)]:[HRD Bin (ppm)]],$B11,TU_DB[[Year]:[Year]],J$6) -> 323 | K11: =COUNTIFS(TU_DB[[HRD Bin (ppm)]:[HRD Bin (ppm)]],$B11,TU_DB[[Year]:[Year]],K$6) -> 180
B12: Total | C12: =SUM(C7:C11) -> 2003 | F12: =SUM(F7:F11) -> 4 | G12: =SUM(G7:G11) -> 108 | H12: =SUM(H7:H11) -> 361 | I12: =SUM(I7:I11) -> 419 | J12: =SUM(J7:J11) -> 714 | K12: =SUM(K7:K11) -> 397
B17: Weather Conditions
C18: Hardness [ppm CaCO3] | J18: Table Labels
B19: Weather Conditions | C19: 0 | D19: 30 | E19: 60 | F19: 120 | G19: 180 | H19: Sum | I19: % Total
B20: Local Thunderstorm | C20: =COUNTIFS(TU_DB[[HRD Bin (ppm)]:[HRD Bin (ppm)]],C$19,TU_DB[[Weather]:[Weather]],$B20) -> 2 | D20: =COUNTIFS(TU_DB[[HRD Bin (ppm)]:[HRD Bin (ppm)]],D$19,TU_DB[[Weather]:[Weather]],$B20) -> 5 | E20: =COUNTIFS(TU_DB[[HRD Bin (ppm)]:[HRD Bin (ppm)]],E$19,TU_DB[[Weather]:[Weather]],$B20) -> 19 | F20: =COUNTIFS(TU_DB[[HRD Bin (ppm)]:[HRD Bin (ppm)]],F$19,TU_DB[[Weather]:[Weather]],$B20) -> 27 | G20: =COUNTIFS(TU_DB[[HRD Bin (ppm)]:[HRD Bin (ppm)]],G$19,TU_DB[[Weather]:[Weather]],$B20) -> 31 | H20: =SUM(C20:G20) -> 84 | I20: =SUM(H20)/SUM($H$20:$H$25) -> 0.047457627 | J20: LT
B21: Regional Rainfall | C21: =COUNTIFS(TU_DB[[HRD Bin (ppm)]:[HRD Bin (ppm)]],C$19,TU_DB[[Weather]:[Weather]],$B21) -> 25 | D21: =COUNTIFS(TU_DB[[HRD Bin (ppm)]:[HRD Bin (ppm)]],D$19,TU_DB[[Weather]:[Weather]],$B21) -> 16 | E21: =COUNTIFS(TU_DB[[HRD Bin (ppm)]:[HRD Bin (ppm)]],E$19,TU_DB[[Weather]:[Weather]],$B21) -> 33 | F21: =COUNTIFS(TU_DB[[HRD Bin (ppm)]:[HRD Bin (ppm)]],F$19,TU_DB[[Weather]:[Weather]],$B21) -> 87 | G21: =COUNTIFS(TU_DB[[HRD Bin (ppm)]:[HRD Bin (ppm)]],G$19,TU_DB[[Weather]:[Weather]],$B21) -> 84 | H21: =SUM(C21:G21) -> 245 | I21: =SUM(H21)/SUM($H$20:$H$25) -> 0.13841808 | J21: RR
B22: Regional Rainfall,Local Thunderstorm | C22: =COUNTIFS(TU_DB[[HRD Bin (ppm)]:[HRD Bin (ppm)]],C$19,TU_DB[[Weather]:[Weather]],$B22) -> 1 | D22: =COUNTIFS(TU_DB[[HRD Bin (ppm)]:[HRD Bin (ppm)]],D$19,TU_DB[[Weather]:[Weather]],$B22) -> 0 | E22: =COUNTIFS(TU_DB[[HRD Bin (ppm)]:[HRD Bin (ppm)]],E$19,TU_DB[[Weather]:[Weather]],$B22) -> 0 | F22: =COUNTIFS(TU_DB[[HRD Bin (ppm)]:[HRD Bin (ppm)]],F$19,TU_DB[[Weather]:[Weather]],$B22) -> 6 | G22: =COUNTIFS(TU_DB[[HRD Bin (ppm)]:[HRD Bin (ppm)]],G$19,TU_DB[[Weather]:[Weather]],$B22) -> 3 | H22: =SUM(C22:G22) -> 10 | I22: =SUM(H22)/SUM($H$20:$H$25) -> 0.0056497175 | J22: RR, LT
B23: Regional Rainfall,Warmth Causing Snowmelt | C23: =COUNTIFS(TU_DB[[HRD Bin (ppm)]:[HRD Bin (ppm)]],C$19,TU_DB[[Weather]:[Weather]],$B23) -> 0 | D23: =COUNTIFS(TU_DB[[HRD Bin (ppm)]:[HRD Bin (ppm)]],D$19,TU_DB[[Weather]:[Weather]],$B23) -> 0 | E23: =COUNTIFS(TU_DB[[HRD Bin (ppm)]:[HRD Bin (ppm)]],E$19,TU_DB[[Weather]:[Weather]],$B23) -> 1 | F23: =COUNTIFS(TU_DB[[HRD Bin (ppm)]:[HRD Bin (ppm)]],F$19,TU_DB[[Weather]:[Weather]],$B23) -> 2 | G23: =COUNTIFS(TU_DB[[HRD Bin (ppm)]:[HRD Bin (ppm)]],G$19,TU_DB[[Weather]:[Weather]],$B23) -> 2 | H23: =SUM(C23:G23) -> 5 | I23: =SUM(H23)/SUM($H$20:$H$25) -> 0.0028248588 | J23: RR, SM
B24: Warmth Causing Snowmelt | C24: =COUNTIFS(TU_DB[[HRD Bin (ppm)]:[HRD Bin (ppm)]],C$19,TU_DB[[Weather]:[Weather]],$B24) -> 0 | D24: =COUNTIFS(TU_DB[[HRD Bin (ppm)]:[HRD Bin (ppm)]],D$19,TU_DB[[Weather]:[Weather]],$B24) -> 1 | E24: =COUNTIFS(TU_DB[[HRD Bin (ppm)]:[HRD Bin (ppm)]],E$19,TU_DB[[Weather]:[Weather]],$B24) -> 6 | F24: =COUNTIFS(TU_DB[[HRD Bin (ppm)]:[HRD Bin (ppm)]],F$19,TU_DB[[Weather]:[Weather]],$B24) -> 7 | G24: =COUNTIFS(TU_DB[[HRD Bin (ppm)]:[HRD Bin (ppm)]],G$19,TU_DB[[Weather]:[Weather]],$B24) -> 6 | H24: =SUM(C24:G24) -> 20 | I24: =SUM(H24)/SUM($H$20:$H$25) -> 0.011299435 | J24: SM
B25: None | C25: =COUNTIFS(TU_DB[[HRD Bin (ppm)]:[HRD Bin (ppm)]],C$19,TU_DB[[Weather]:[Weather]],$B25) -> 76 | D25: =COUNTIFS(TU_DB[[HRD Bin (ppm)]:[HRD Bin (ppm)]],D$19,TU_DB[[Weather]:[Weather]],$B25) -> 91 | E25: =COUNTIFS(TU_DB[[HRD Bin (ppm)]:[HRD Bin (ppm)]],E$19,TU_DB[[Weather]:[Weather]],$B25) -> 122 | F25: =COUNTIFS(TU_DB[[HRD Bin (ppm)]:[HRD Bin (ppm)]],F$19,TU_DB[[Weather]:[Weather]],$B25) -> 489 | G25: =COUNTIFS(TU_DB[[HRD Bin (ppm)]:[HRD Bin (ppm)]],G$19,TU_DB[[Weather]:[Weather]],$B25) -> 628 | H25: =SUM(C25:G25) -> 1406 | I25: =SUM(H25)/SUM($H$20:$H$25) -> 0.79435028 | J25: None
B26: Total | C26: =SUM(C20:C25) -> 104 | D26: =SUM(D20:D25) -> 113 | E26: =SUM(E20:E25) -> 181 | F26: =SUM(F20:F25) -> 618 | G26: =SUM(G20:G25) -> 754 | H26: =SUM(H20:H25) -> 1770
B28: Water Level
C29: Hardness [ppm CaCO3]
B30: Water Level | C30: 0 | D30: 30 | E30: 60 | F30: 120 | G30: 180 | H30: Sum | I30: % Total
B31: Baseflow | C31: =COUNTIFS(TU_DB[[HRD Bin (ppm)]:[HRD Bin (ppm)]],C$19,TU_DB[[Water Level]:[Water Level]],$B31) -> 71 | D31: =COUNTIFS(TU_DB[[HRD Bin (ppm)]:[HRD Bin (ppm)]],D$19,TU_DB[[Water Level]:[Water Level]],$B31) -> 83 | E31: =COUNTIFS(TU_DB[[HRD Bin (ppm)]:[HRD Bin (ppm)]],E$19,TU_DB[[Water Level]:[Water Level]],$B31) -> 137 | F31: =COUNTIFS(TU_DB[[HRD Bin (ppm)]:[HRD Bin (ppm)]],F$19,TU_DB[[Water Level]:[Water Level]],$B31) -> 485 | G31: =COUNTIFS(TU_DB[[HRD Bin (ppm)]:[HRD Bin (ppm)]],G$19,TU_DB[[Water Level]:[Water Level]],$B31) -> 597 | H31: =SUM(C31:G31) -> 1373 | I31: =SUM(H31)/SUM($H$31:$H$34) -> 0.75814467
B32: Mid-Stage | C32: =COUNTIFS(TU_DB[[HRD Bin (ppm)]:[HRD Bin (ppm)]],C$19,TU_DB[[Water Level]:[Water Level]],$B32) -> 32 | D32: =COUNTIFS(TU_DB[[HRD Bin (ppm)]:[HRD Bin (ppm)]],D$19,TU_DB[[Water Level]:[Water Level]],$B32) -> 26 | E32: =COUNTIFS(TU_DB[[HRD Bin (ppm)]:[HRD Bin (ppm)]],E$19,TU_DB[[Water Level]:[Water Level]],$B32) -> 28 | F32: =COUNTIFS(TU_DB[[HRD Bin (ppm)]:[HRD Bin (ppm)]],F$19,TU_DB[[Water Level]:[Water Level]],$B32) -> 118 | G32: =COUNTIFS(TU_DB[[HRD Bin (ppm)]:[HRD Bin (ppm)]],G$19,TU_DB[[Water Level]:[Water Level]],$B32) -> 153 | H32: =SUM(C32:G32) -> 357 | I32: =SUM(H32)/SUM($H$31:$H$34) -> 0.19712866
